Traceback (most recent call last):
  File "<frozen importlib._bootstrap_external>", line 1485, in _path_importer_cache
KeyError: '/home/alexander/lib/python3.12/site-packages/numpy/core'

During handling of the above exception, another exception occurred:

Traceback (most recent call last):
  File "/home/alexander/school/exeter/phd-physics/upgrade_report/case_studies/common/structures/interfaces/120_C84Si36_012_012_a0.636364_b0.117284_c1.482413_interface14shift2/run-mace.py", line 4, in <module>
    from ase.io import read
  File "/home/alexander/lib/python3.12/site-packages/ase/__init__.py", line 8, in <module>
    import ase.parallel  # noqa
    ^^^^^^^^^^^^^^^^^^^
  File "/home/alexander/lib/python3.12/site-packages/ase/parallel.py", line 9, in <module>
    import numpy as np
  File "/home/alexander/lib/python3.12/site-packages/numpy/__init__.py", line 130, in <module>
    from numpy.__config__ import show as show_config
  File "/home/alexander/lib/python3.12/site-packages/numpy/__config__.py", line 4, in <module>
    from numpy.core._multiarray_umath import (
  File "/home/alexander/lib/python3.12/site-packages/numpy/core/__init__.py", line 24, in <module>
    from . import multiarray
  File "<frozen importlib._bootstrap>", line 1360, in _find_and_load
  File "<frozen importlib._bootstrap>", line 1322, in _find_and_load_unlocked
  File "<frozen importlib._bootstrap>", line 1262, in _find_spec
  File "<frozen importlib._bootstrap_external>", line 1528, in find_spec
  File "<frozen importlib._bootstrap_external>", line 1500, in _get_spec
  File "<frozen importlib._bootstrap_external>", line 1487, in _path_importer_cache
  File "<frozen importlib._bootstrap_external>", line 1463, in _path_hooks
  File "<frozen zipimport>", line 75, in __init__
  File "<frozen importlib._bootstrap_external>", line 140, in _path_stat
KeyboardInterrupt
