Traceback (most recent call last):
  File "<frozen importlib._bootstrap_external>", line 1485, in _path_importer_cache
KeyError: '/home/alexander/lib/python3.12/site-packages/numpy'

During handling of the above exception, another exception occurred:

Traceback (most recent call last):
  File "/home/alexander/school/exeter/phd-physics/upgrade_report/case_studies/common/structures/interfaces/120_C84Si36_012_012_a0.395062_b0.104938_c1.680068_interface2shift3/run-mace.py", line 4, in <module>
    from ase.io import read
  File "/home/alexander/lib/python3.12/site-packages/ase/__init__.py", line 8, in <module>
    import ase.parallel  # noqa
    ^^^^^^^^^^^^^^^^^^^
  File "/home/alexander/lib/python3.12/site-packages/ase/parallel.py", line 9, in <module>
    import numpy as np
  File "/home/alexander/lib/python3.12/site-packages/numpy/__init__.py", line 105, in <module>
    from ._globals import _NoValue, _CopyMode
  File "<frozen importlib._bootstrap>", line 1360, in _find_and_load
  File "<frozen importlib._bootstrap>", line 1322, in _find_and_load_unlocked
  File "<frozen importlib._bootstrap>", line 1262, in _find_spec
  File "<frozen importlib._bootstrap_external>", line 1528, in find_spec
  File "<frozen importlib._bootstrap_external>", line 1500, in _get_spec
  File "<frozen importlib._bootstrap_external>", line 1487, in _path_importer_cache
  File "<frozen importlib._bootstrap_external>", line 1463, in _path_hooks
  File "<frozen importlib._bootstrap_external>", line 1687, in path_hook_for_FileFinder
  File "<frozen importlib._bootstrap_external>", line 168, in _path_isdir
  File "<frozen importlib._bootstrap_external>", line 153, in _path_is_mode_type
  File "<frozen importlib._bootstrap_external>", line 147, in _path_stat
KeyboardInterrupt
